Workbook
Name NativeTimeline_Order_Date: #N/A
Name Slicer_Category: #N/A
Name Slicer_Channel: #N/A
Name Slicer_Region: #N/A
Name Slicer_Segment: #N/A
Name Slicer_Year: #N/A

Sheet Dashboard
B1: Retail Sales Performance Dashboard
B2: FY2023–FY2025 | Revenue, Profit & Margin Analysis | Use the filters on the left
G5: Total Revenue | K5: Total Profit | O5: Margin % | S5: Total Units | W5: Total Orders
G6: =GETPIVOTDATA("Total Revenue",Pivots!$A$3) -> 82861183 | K6: =GETPIVOTDATA("Total Profit",Pivots!$A$3) -> 14823504 | O6: =GETPIVOTDATA("Margin %",Pivots!$A$3) -> 0.17889563 | S6: =GETPIVOTDATA("Total Units",Pivots!$A$3) -> 10543 | W6: =GETPIVOTDATA("Total Orders",Pivots!$A$3) -> 4500
B29: Select Year | C29: 2025
B32: Region | C32: Annual Target | D32: Actual Revenue | E32: Achievement % | F32: Target vs Actual (Revenue)
B33: North | C33: =INDEX(Targets!$B$2:$B$5,MATCH(B33,Targets!$A$2:$A$5,0)) -> 7500000 | D33: =SUMIFS(tblSales[Revenue],tblSales[Region],B33,tblSales[Year],Dashboard!$C$29) -> 7826480.4 | E33: =IF(C33=0,0,D33/C33) -> 1.0435307 | F33: =D33-C33 -> 326480.4
B34: South | C34: =INDEX(Targets!$B$2:$B$5,MATCH(B34,Targets!$A$2:$A$5,0)) -> 9000000 | D34: =SUMIFS(tblSales[Revenue],tblSales[Region],B34,tblSales[Year],Dashboard!$C$29) -> 8609317.7 | E34: =IF(C34=0,0,D34/C34) -> 0.95659085 | F34: =D34-C34 -> -390682.35
B35: East | C35: =INDEX(Targets!$B$2:$B$5,MATCH(B35,Targets!$A$2:$A$5,0)) -> 5000000 | D35: =SUMIFS(tblSales[Revenue],tblSales[Region],B35,tblSales[Year],Dashboard!$C$29) -> 4649217.7 | E35: =IF(C35=0,0,D35/C35) -> 0.92984354 | F35: =D35-C35 -> -350782.3
B36: West | C36: =INDEX(Targets!$B$2:$B$5,MATCH(B36,Targets!$A$2:$A$5,0)) -> 9500000 | D36: =SUMIFS(tblSales[Revenue],tblSales[Region],B36,tblSales[Year],Dashboard!$C$29) -> 8723458.4 | E36: =IF(C36=0,0,D36/C36) -> 0.91825878 | F36: =D36-C36 -> -776541.6
B37: Total | C37: =SUM(C33:C36) -> 31000000 | D37: =SUM(D33:D36) -> 29808474 | E37: =IF(C37=0,0,D37/C37) -> 0.96156368 | F37: =D37-C37 -> -1191525.9

Sheet Project_Brief
A1: RETAIL SALES PERFORMANCE – DECISION DASHBOARD
A2: Business: Multi-category retailer, 12 stores, 4 regions, 3 channels, FY2023–FY2025 (synthetic data, INR).
A4: DECISION QUESTIONS TO ANSWER
A5: 1. Which regions/categories drive profit, and which only drive revenue?
A6: 2. Are discounts destroying margin anywhere? Where should discount caps apply?
A7: 3. Which sub-categories should be expanded, repriced or phased out?
A8: 4. How is the channel mix shifting, and what does it do to profitability?
A9: 5. What inventory/staffing plan should we adopt for the Oct–Dec peak?
A11: HOW TO USE THIS FILE
A12: Sales_Data is an Excel Table (tblSales). Insert > PivotTable > Table: tblSales. Revenue, Cost, Profit and Margin are formulas.
A13: Targets holds regional targets for target-vs-actual (blue cells are inputs).
A14: Build pivots on a 'Pivots' sheet and the visuals on a 'Dashboard' sheet, following the guide in the chat.

Sheet Sales_Data
A1: Order ID | B1: Order Date | C1: Year | D1: Month No | E1: Month | F1: Quarter | G1: Region | H1: State | I1: Store | J1: Category | K1: Sub-Category | L1: Segment | M1: Channel | N1: Units | O1: List Price | P1: Discount % | Q1: Unit Cost | R1: Revenue | S1: Cost | T1: Profit | U1: Profit Margin % | V1: Returned
A2: ORD-101523 | B2: 44928 | C2: =YEAR(B2) -> 2023 | D2: =MONTH(B2) -> 1 | E2: =TEXT(B2,"mmm") -> Jan | F2: ="Q"&ROUNDUP(D2/3,0) -> Q1 | G2: East | H2: West Bengal | I2: West Bengal Mega Store | J2: Technology | K2: Laptops | L2: Consumer | M2: Marketplace | N2: 3 | O2: 48013 | P2: 0.05 | Q2: 40918 | R2: =N2*O2*(1-P2) -> 136837.05 | S2: =N2*Q2 -> 122754 | T2: =R2-S2 -> 14083.05 | U2: =IF(R2=0,0,T2/R2) -> 0.1029184 | V2: No
A3: ORD-103100 | B3: 44928 | C3: =YEAR(B3) -> 2023 | D3: =MONTH(B3) -> 1 | E3: =TEXT(B3,"mmm") -> Jan | F3: ="Q"&ROUNDUP(D3/3,0) -> Q1 | G3: East | H3: Bihar | I3: Bihar Mega Store | J3: Office Supplies | K3: Paper | L3: Small Business | M3: In-Store | N3: 1 | O3: 490 | P3: 0 | Q3: 221 | R3: =N3*O3*(1-P3) -> 490 | S3: =N3*Q3 -> 221 | T3: =R3-S3 -> 269 | U3: =IF(R3=0,0,T3/R3) -> 0.54897959 | V3: No
A4: ORD-103449 | B4: 44928 | C4: =YEAR(B4) -> 2023 | D4: =MONTH(B4) -> 1 | E4: =TEXT(B4,"mmm") -> Jan | F4: ="Q"&ROUNDUP(D4/3,0) -> Q1 | G4: West | H4: Maharashtra | I4: Maharashtra Mega Store | J4: Clothing | K4: Footwear | L4: Small Business | M4: Online | N4: 1 | O4: 3000 | P4: 0.15 | Q4: 1746 | R4: =N4*O4*(1-P4) -> 2550 | S4: =N4*Q4 -> 1746 | T4: =R4-S4 -> 804 | U4: =IF(R4=0,0,T4/R4) -> 0.31529412 | V4: No
A5: ORD-103936 | B5: 44928 | C5: =YEAR(B5) -> 2023 | D5: =MONTH(B5) -> 1 | E5: =TEXT(B5,"mmm") -> Jan | F5: ="Q"&ROUNDUP(D5/3,0) -> Q1 | G5: South | H5: Karnataka | I5: Karnataka Mega Store | J5: Office Supplies | K5: Art | L5: Small Business | M5: Marketplace | N5: 1 | O5: 268 | P5: 0.05 | Q5: 113 | R5: =N5*O5*(1-P5) -> 254.6 | S5: =N5*Q5 -> 113 | T5: =R5-S5 -> 141.6 | U5: =IF(R5=0,0,T5/R5) -> 0.55616654 | V5: No
A6: ORD-104348 | B6: 44928 | C6: =YEAR(B6) -> 2023 | D6: =MONTH(B6) -> 1 | E6: =TEXT(B6,"mmm") -> Jan | F6: ="Q"&ROUNDUP(D6/3,0) -> Q1 | G6: North | H6: Delhi | I6: Delhi Mega Store | J6: Office Supplies | K6: Binders | L6: Small Business | M6: Marketplace | N6: 2 | O6: 311 | P6: 0.05 | Q6: 121 | R6: =N6*O6*(1-P6) -> 590.9 | S6: =N6*Q6 -> 242 | T6: =R6-S6 -> 348.9 | U6: =IF(R6=0,0,T6/R6) -> 0.59045524 | V6: No
A7: ORD-104500 | B7: 44928 | C7: =YEAR(B7) -> 2023 | D7: =MONTH(B7) -> 1 | E7: =TEXT(B7,"mmm") -> Jan | F7: ="Q"&ROUNDUP(D7/3,0) -> Q1 | G7: South | H7: Andhra Pradesh | I7: Andhra Pradesh Mega Store | J7: Office Supplies | K7: Paper | L7: Small Business | M7: In-Store | N7: 5 | O7: 422 | P7: 0.05 | Q7: 185 | R7: =N7*O7*(1-P7) -> 2004.5 | S7: =N7*Q7 -> 925 | T7: =R7-S7 -> 1079.5 | U7: =IF(R7=0,0,T7/R7) -> 0.53853829 | V7: No
A8: ORD-101067 | B8: 44929 | C8: =YEAR(B8) -> 2023 | D8: =MONTH(B8) -> 1 | E8: =TEXT(B8,"mmm") -> Jan | F8: ="Q"&ROUNDUP(D8/3,0) -> Q1 | G8: North | H8: Delhi | I8: Delhi Mega Store | J8: Office Supplies | K8: Paper | L8: Consumer | M8: In-Store | N8: 4 | O8: 435 | P8: 0.15 | Q8: 193 | R8: =N8*O8*(1-P8) -> 1479 | S8: =N8*Q8 -> 772 | T8: =R8-S8 -> 707 | U8: =IF(R8=0,0,T8/R8) -> 0.47802569 | V8: No
A9: ORD-101486 | B9: 44929 | C9: =YEAR(B9) -> 2023 | D9: =MONTH(B9) -> 1 | E9: =TEXT(B9,"mmm") -> Jan | F9: ="Q"&ROUNDUP(D9/3,0) -> Q1 | G9: South | H9: Tamil Nadu | I9: Tamil Nadu Mega Store | J9: Office Supplies | K9: Binders | L9: Consumer | M9: Online | N9: 2 | O9: 288 | P9: 0.05 | Q9: 117 | R9: =N9*O9*(1-P9) -> 547.2 | S9: =N9*Q9 -> 234 | T9: =R9-S9 -> 313.2 | U9: =IF(R9=0,0,T9/R9) -> 0.57236842 | V9: No
A10: ORD-102365 | B10: 44929 | C10: =YEAR(B10) -> 2023 | D10: =MONTH(B10) -> 1 | E10: =TEXT(B10,"mmm") -> Jan | F10: ="Q"&ROUNDUP(D10/3,0) -> Q1 | G10: North | H10: Delhi | I10: Delhi Mega Store | J10: Technology | K10: Printers | L10: Corporate | M10: In-Store | N10: 3 | O10: 10213 | P10: 0.1 | Q10: 7618 | R10: =N10*O10*(1-P10) -> 27575.1 | S10: =N10*Q10 -> 22854 | T10: =R10-S10 -> 4721.1 | U10: =IF(R10=0,0,T10/R10) -> 0.17120881 | V10: No
A11: ORD-103470 | B11: 44929 | C11: =YEAR(B11) -> 2023 | D11: =MONTH(B11) -> 1 | E11: =TEXT(B11,"mmm") -> Jan | F11: ="Q"&ROUNDUP(D11/3,0) -> Q1 | G11: East | H11: West Bengal | I11: West Bengal Mega Store | J11: Office Supplies | K11: Art | L11: Small Business | M11: In-Store | N11: 3 | O11: 260 | P11: 0 | Q11: 110 | R11: =N11*O11*(1-P11) -> 780 | S11: =N11*Q11 -> 330 | T11: =R11-S11 -> 450 | U11: =IF(R11=0,0,T11/R11) -> 0.57692308 | V11: No
A12: ORD-103495 | B12: 44929 | C12: =YEAR(B12) -> 2023 | D12: =MONTH(B12) -> 1 | E12: =TEXT(B12,"mmm") -> Jan | F12: ="Q"&ROUNDUP(D12/3,0) -> Q1 | G12: West | H12: Rajasthan | I12: Rajasthan Mega Store | J12: Furniture | K12: Chairs | L12: Consumer | M12: Marketplace | N12: 3 | O12: 6854 | P12: 0.35 | Q12: 3711 | R12: =N12*O12*(1-P12) -> 13365.3 | S12: =N12*Q12 -> 11133 | T12: =R12-S12 -> 2232.3 | U12: =IF(R12=0,0,T12/R12) -> 0.16702206 | V12: No
A13: ORD-100381 | B13: 44930 | C13: =YEAR(B13) -> 2023 | D13: =MONTH(B13) -> 1 | E13: =TEXT(B13,"mmm") -> Jan | F13: ="Q"&ROUNDUP(D13/3,0) -> Q1 | G13: West | H13: Maharashtra | I13: Maharashtra Mega Store | J13: Clothing | K13: Womenswear | L13: Corporate | M13: Online | N13: 5 | O13: 2590 | P13: 0.05 | Q13: 1302 | R13: =N13*O13*(1-P13) -> 12302.5 | S13: =N13*Q13 -> 6510 | T13: =R13-S13 -> 5792.5 | U13: =IF(R13=0,0,T13/R13) -> 0.47083926 | V13: No
... A4501: ORD-104222 | B4501: 46022 | C4501: =YEAR(B4501) -> 2025 | D4501: =MONTH(B4501) -> 12 | E4501: =TEXT(B4501,"mmm") -> Dec | F4501: ="Q"&ROUNDUP(D4501/3,0) -> Q4 | G4501: West | H4501: Maharashtra | I4501: Maharashtra Mega Store | J4501: Furniture | K4501: Sofas | L4501: Consumer | M4501: Online | N4501: 2 | O4501: 29502 | P4501: 0.35 | Q4501: 20475 | R4501: =N4501*O4501*(1-P4501) -> 38352.6 | S4501: =N4501*Q4501 -> 40950 | T4501: =R4501-S4501 -> -2597.4 | U4501: =IF(R4501=0,0,T4501/R4501) -> -0.067724222 | V4501: No

Sheet Detail1
A1: Details for Total Profit
A3: Order ID | B3: Order Date | C3: Year | D3: Month No | E3: Month | F3: Quarter | G3: Region | H3: State | I3: Store | J3: Category | K3: Sub-Category | L3: Segment | M3: Channel | N3: Units | O3: List Price | P3: Discount % | Q3: Unit Cost | R3: Revenue | S3: Cost | T3: Profit | U3: Profit Margin % | V3: Returned
A4: ORD-104222 | B4: 46022 | C4: 2025 | D4: 12 | E4: Dec | F4: Q4 | G4: West | H4: Maharashtra | I4: Maharashtra Mega Store | J4: Furniture | K4: Sofas | L4: Consumer | M4: Online | N4: 2 | O4: 29502 | P4: 0.35 | Q4: 20475 | R4: 38352.6 | S4: 40950 | T4: -2597.4 | U4: -0.067724222 | V4: No
A5: ORD-100252 | B5: 46022 | C5: 2025 | D5: 12 | E5: Dec | F5: Q4 | G5: West | H5: Maharashtra | I5: Maharashtra Mega Store | J5: Furniture | K5: Chairs | L5: Corporate | M5: Online | N5: 3 | O5: 6485 | P5: 0.2 | Q5: 3493 | R5: 15564 | S5: 10479 | T5: 5085 | U5: 0.3267155 | V5: No
A6: ORD-103449 | B6: 44928 | C6: 2023 | D6: 1 | E6: Jan | F6: Q1 | G6: West | H6: Maharashtra | I6: Maharashtra Mega Store | J6: Clothing | K6: Footwear | L6: Small Business | M6: Online | N6: 1 | O6: 3000 | P6: 0.15 | Q6: 1746 | R6: 2550 | S6: 1746 | T6: 804 | U6: 0.31529412 | V6: No
A7: ORD-103802 | B7: 46021 | C7: 2025 | D7: 12 | E7: Dec | F7: Q4 | G7: West | H7: Rajasthan | I7: Rajasthan Mega Store | J7: Office Supplies | K7: Binders | L7: Corporate | M7: In-Store | N7: 2 | O7: 283 | P7: 0.15 | Q7: 111 | R7: 481.1 | S7: 222 | T7: 259.1 | U7: 0.53855747 | V7: No
A8: ORD-102328 | B8: 46021 | C8: 2025 | D8: 12 | E8: Dec | F8: Q4 | G8: West | H8: Maharashtra | I8: Maharashtra Mega Store | J8: Office Supplies | K8: Binders | L8: Corporate | M8: In-Store | N8: 4 | O8: 329 | P8: 0.05 | Q8: 128 | R8: 1250.2 | S8: 512 | T8: 738.2 | U8: 0.59046553 | V8: Yes
A9: ORD-100944 | B9: 46021 | C9: 2025 | D9: 12 | E9: Dec | F9: Q4 | G9: West | H9: Gujarat | I9: Gujarat Mega Store | J9: Clothing | K9: Footwear | L9: Consumer | M9: Online | N9: 4 | O9: 2672 | P9: 0.15 | Q9: 1602 | R9: 9084.8 | S9: 6408 | T9: 2676.8 | U9: 0.294646 | V9: Yes
A10: ORD-104492 | B10: 46020 | C10: 2025 | D10: 12 | E10: Dec | F10: Q4 | G10: West | H10: Rajasthan | I10: Rajasthan Mega Store | J10: Office Supplies | K10: Paper | L10: Corporate | M10: In-Store | N10: 1 | O10: 421 | P10: 0.1 | Q10: 184 | R10: 378.9 | S10: 184 | T10: 194.9 | U10: 0.51438374 | V10: No
A11: ORD-103899 | B11: 46020 | C11: 2025 | D11: 12 | E11: Dec | F11: Q4 | G11: West | H11: Gujarat | I11: Gujarat Mega Store | J11: Technology | K11: Phones | L11: Corporate | M11: Marketplace | N11: 1 | O11: 16824 | P11: 0.2 | Q11: 13113 | R11: 13459.2 | S11: 13113 | T11: 346.2 | U11: 0.025722183 | V11: No
A12: ORD-103132 | B12: 46019 | C12: 2025 | D12: 12 | E12: Dec | F12: Q4 | G12: West | H12: Maharashtra | I12: Maharashtra Mega Store | J12: Technology | K12: Laptops | L12: Consumer | M12: Online | N12: 1 | O12: 46922 | P12: 0 | Q12: 40595 | R12: 46922 | S12: 40595 | T12: 6327 | U12: 0.1348408 | V12: No
A13: ORD-101695 | B13: 46019 | C13: 2025 | D13: 12 | E13: Dec | F13: Q4 | G13: West | H13: Maharashtra | I13: Maharashtra Mega Store | J13: Office Supplies | K13: Art | L13: Consumer | M13: Marketplace | N13: 3 | O13: 234 | P13: 0.05 | Q13: 101 | R13: 666.9 | S13: 303 | T13: 363.9 | U13: 0.54565902 | V13: No
A14: ORD-103495 | B14: 44929 | C14: 2023 | D14: 1 | E14: Jan | F14: Q1 | G14: West | H14: Rajasthan | I14: Rajasthan Mega Store | J14: Furniture | K14: Chairs | L14: Consumer | M14: Marketplace | N14: 3 | O14: 6854 | P14: 0.35 | Q14: 3711 | R14: 13365.3 | S14: 11133 | T14: 2232.3 | U14: 0.16702206 | V14: No
A15: ORD-100381 | B15: 44930 | C15: 2023 | D15: 1 | E15: Jan | F15: Q1 | G15: West | H15: Maharashtra | I15: Maharashtra Mega Store | J15: Clothing | K15: Womenswear | L15: Corporate | M15: Online | N15: 5 | O15: 2590 | P15: 0.05 | Q15: 1302 | R15: 12302.5 | S15: 6510 | T15: 5792.5 | U15: 0.47083926 | V15: No
... A1507: ORD-102407 | B1507: 45299 | C1507: 2024 | D1507: 1 | E1507: Jan | F1507: Q1 | G1507: West | H1507: Gujarat | I1507: Gujarat Mega Store | J1507: Office Supplies | K1507: Paper | L1507: Corporate | M1507: Marketplace | N1507: 1 | O1507: 465 | P1507: 0.05 | Q1507: 214 | R1507: 441.75 | S1507: 214 | T1507: 227.75 | U1507: 0.5155631 | V1507: No

Sheet Pivots
A3: Margin % | B3: Total Revenue | C3: Total Profit | D3: Total Units | E3: Total Orders | G3: Year | H3: Month No | I3: Total Revenue | J3: Total Profit | L3: Row Labels | M3: Total Revenue | N3: Total Profit | O3: Margin % | R3: Category | S3: Sub-Category | T3: Total Revenue | U3: Total Profit | V3: Margin % | Y3: Total Revenue | Z3: Column Labels | AF3: Row Labels | AG3: Total Revenue | AH3: Margin % | AL3: Row Labels | AM3: Total Profit | AO3: Row Labels | AP3: Total Profit | AR3: Orders | AS3: Column Labels | AX3: Category | AY3: Sub-Category | AZ3: Margin %
A4: 0.17889563 | B4: 82861183 | C4: 14823504 | D4: 10543 | E4: 4500 | G4: 2023 | H4: 1 | I4: 2001417.3 | J4: 389065.3 | L4: South | M4: 23698095 | N4: 4531198.7 | O4: 0.19120519 | R4: Clothing | S4: Footwear | T4: 1844600 | U4: 640953.95 | V4: 0.34747586 | Y4: Row Labels | Z4: In-Store | AA4: Marketplace | AB4: Online | AC4: Grand Total | AF4: 0 | AG4: 22969928 | AH4: 0.2500522 | AL4: Sofas | AM4: 2957684.8 | AO4: Art | AP4: 123770.9 | AR4: Row Labels | AS4: No | AT4: Yes | AU4: Grand Total | AX4: Clothing | AY4: Footwear | AZ4: 0.34747586
H5: 2 | I5: 1700592 | J5: 338984 | L5: West | M5: 25940318 | N5: 3759734.6 | O5: 0.14493788 | S5: Menswear | T5: 1190316.3 | U5: 527924.25 | V5: 0.44351596 | Y5: 2023 | Z5: 0.5243963 | AA5: 0.16746356 | AB5: 0.30814014 | AC5: 1 | AF5: 0.05 | AG5: 18840446 | AH5: 0.20153805 | AL5: Laptops | AM5: 2653172.2 | AO5: Binders | AP5: 156418.3 | AR5: Clothing | AS5: 0.8872267 | AT5: 0.1127733 | AU5: 1 | AY5: Menswear | AZ5: 0.44351596
H6: 3 | I6: 1769452.3 | J6: 330390.25 | L6: North | M6: 19867572 | N6: 3745267.4 | O6: 0.18851158 | S6: Womenswear | T6: 1485670.7 | U6: 686947.75 | V6: 0.46238223 | Y6: 2024 | Z6: 0.46807483 | AA6: 0.18274439 | AB6: 0.34918078 | AC6: 1 | AF6: 0.1 | AG6: 13681891 | AH6: 0.17060075 | AL6: Phones | AM6: 1739420.2 | AO6: Paper | AP6: 190152.55 | AR6: Furniture | AS6: 0.96296296 | AT6: 0.037037037 | AU6: 1 | AY6: Womenswear | AZ6: 0.46238223
H7: 4 | I7: 2132091.4 | J7: 282839.45 | L7: East | M7: 13355198 | N7: 2787303.1 | O7: 0.20870549 | R7: Clothing Total | T7: 4520587 | U7: 1855826 | V7: 0.41052765 | Y7: 2025 | Z7: 0.4023906 | AA7: 0.21678042 | AB7: 0.38082898 | AC7: 1 | AF7: 0.15 | AG7: 13884629 | AH7: 0.1021936 | AL7: Printers | AM7: 1253861.4 | AO7: Accessories | AP7: 464371.2 | AR7: Office Supplies | AS7: 0.95726496 | AT7: 0.042735043 | AU7: 1 | AX7: Clothing Total | AZ7: 0.41052765
H8: 5 | I8: 1685029.7 | J8: 352214.7 | L8: Grand Total | M8: 82861183 | N8: 14823504 | O8: 0.17889563 | R8: Furniture | S8: Tables | T8: 5121520.3 | U8: 739906.35 | V8: 0.14447006 | Y8: Grand Total | Z8: 0.46212808 | AA8: 0.19019099 | AB8: 0.34768093 | AC8: 1 | AF8: 0.2 | AG8: 5431377.6 | AH8: 0.16153979 | AL8: Bookcases | AM8: 975117.15 | AO8: Menswear | AP8: 527924.25 | AR8: Technology | AS8: 0.96280277 | AT8: 0.037197232 | AU8: 1 | AX8: Furniture | AY8: Tables | AZ8: 0.14447006
H9: 6 | I9: 2261016.7 | J9: 350172.65 | S9: Sofas | T9: 14339834 | U9: 2957684.8 | V9: 0.20625656 | AF9: 0.25 | AG9: 1681099.5 | AH9: 0.15759716 | AL9: Grand Total | AM9: 9579255.8 | AO9: Grand Total | AP9: 1462637.2 | AR9: Grand Total | AS9: 0.94622222 | AT9: 0.053777778 | AU9: 1 | AY9: Sofas | AZ9: 0.20625656
H10: 7 | I10: 2551294.4 | J10: 393098.4 | S10: Bookcases | T10: 3660439.2 | U10: 975117.15 | V10: 0.26639349 | AF10: 0.3 | AG10: 2799602.4 | AH10: 0.10397741 | AY10: Bookcases | AZ10: 0.26639349
H11: 8 | I11: 1652411.9 | J11: 369446.95 | S11: Chairs | T11: 2671012.5 | U11: 937531.5 | V11: 0.35100229 | AF11: 0.35 | AG11: 2829336.9 | AH11: 0.0480971 | AY11: Chairs | AZ11: 0.35100229
H12: 9 | I12: 1819139.1 | J12: 360847.1 | R12: Furniture Total | T12: 25792806 | U12: 5610239.8 | V12: 0.21751181 | AF12: 0.4 | AG12: 742872.6 | AH12: -0.053580385 | AX12: Furniture Total | AZ12: 0.21751181
H13: 10 | I13: 2122044.5 | J13: 452419.5 | R13: Office Supplies | S13: Storage | T13: 2059383.2 | U13: 776271.2 | V13: 0.37694354 | AF13: Grand Total | AG13: 82861183 | AH13: 0.17889563 | AX13: Office Supplies | AY13: Storage | AZ13: 0.37694354
H14: 11 | I14: 3217988.9 | J14: 637329.85 | S14: Paper | T14: 367277.55 | U14: 190152.55 | V14: 0.51773529 | AY14: Paper | AZ14: 0.51773529
H15: 12 | I15: 3102325.4 | J15: 631245.4 | S15: Art | T15: 225550.9 | U15: 123770.9 | V15: 0.54874931 | AY15: Art | AZ15: 0.54874931
G16: 2023 Total | I16: 26014804 | J16: 4888053.6 | S16: Binders | T16: 275307.3 | U16: 156418.3 | V16: 0.56815893 | AY16: Binders | AZ16: 0.56815893
G17: 2024 | H17: 1 | I17: 1550093.4 | J17: 312311.45 | R17: Office Supplies Total | T17: 2927518.9 | U17: 1246612.9 | V17: 0.42582575 | AX17: Office Supplies Total | AZ17: 0.42582575
H18: 2 | I18: 2182566.4 | J18: 415768.4 | R18: Technology | S18: Laptops | T18: 31982155 | U18: 2653172.2 | V18: 0.082957893 | AX18: Technology | AY18: Laptops | AZ18: 0.082957893
H19: 3 | I19: 2919659.6 | J19: 483942.65 | S19: Phones | T19: 10565978 | U19: 1739420.2 | V19: 0.16462463 | AY19: Phones | AZ19: 0.16462463
H20: 4 | I20: 1625353.1 | J20: 309107.05 | S20: Printers | T20: 6073892.4 | U20: 1253861.4 | V20: 0.20643458 | AY20: Printers | AZ20: 0.20643458
A21: Target vs Actual | H21: 5 | I21: 2156017.1 | J21: 373412.15 | S21: Accessories | T21: 998245.2 | U21: 464371.2 | V21: 0.46518751 | AY21: Accessories | AZ21: 0.46518751
H22: 6 | I22: 2439980.6 | J22: 373778.6 | R22: Technology Total | T22: 49620271 | U22: 6110825 | V22: 0.12315179 | AX22: Technology Total | AZ22: 0.12315179
H23: 7 | I23: 2350166.5 | J23: 299737.55 | R23: Grand Total | T23: 82861183 | U23: 14823504 | V23: 0.17889563 | AX23: Grand Total | AZ23: 0.17889563
A24: Region | B24: Annual Target | C24: Actual Revenue | D24: Achievement % | E24: Gap (Actual − Target) | H24: 8 | I24: 2346149.3 | J24: 411332.35
A25: North | B25: =INDEX(Targets!$B$2:$B$5,MATCH(A25,Targets!$A$2:$A$5,0)) -> 7500000 | C25: =SUMIFS(tblSales[Revenue],tblSales[Region],A25,tblSales[Year],Dashboard!$C$29) -> 7826480.4 | D25: =IF(B25=0,0,C25/B25) -> 1.0435307 | E25: =C25-B25 -> 326480.4 | H25: 9 | I25: 1918124.9 | J25: 259543.85
A26: South | B26: =INDEX(Targets!$B$2:$B$5,MATCH(A26,Targets!$A$2:$A$5,0)) -> 9000000 | C26: =SUMIFS(tblSales[Revenue],tblSales[Region],A26,tblSales[Year],Dashboard!$C$29) -> 8609317.7 | D26: =IF(B26=0,0,C26/B26) -> 0.95659085 | E26: =C26-B26 -> -390682.35 | H26: 10 | I26: 2749613.3 | J26: 451295.3
A27: East | B27: =INDEX(Targets!$B$2:$B$5,MATCH(A27,Targets!$A$2:$A$5,0)) -> 5000000 | C27: =SUMIFS(tblSales[Revenue],tblSales[Region],A27,tblSales[Year],Dashboard!$C$29) -> 4649217.7 | D27: =IF(B27=0,0,C27/B27) -> 0.92984354 | E27: =C27-B27 -> -350782.3 | H27: 11 | I27: 2152067.2 | J27: 467434.2
A28: West | B28: =INDEX(Targets!$B$2:$B$5,MATCH(A28,Targets!$A$2:$A$5,0)) -> 9500000 | C28: =SUMIFS(tblSales[Revenue],tblSales[Region],A28,tblSales[Year],Dashboard!$C$29) -> 8723458.4 | D28: =IF(B28=0,0,C28/B28) -> 0.91825878 | E28: =C28-B28 -> -776541.6 | H28: 12 | I28: 2648113.6 | J28: 532916.55
A29: Total | B29: =SUM(B25:B28) -> 31000000 | C29: =SUM(C25:C28) -> 29808474 | D29: =IF(B29=0,0,C29/B29) -> 0.96156368 | E29: =C29-B29 -> -1191525.9 | G29: 2024 Total | I29: 27037905 | J29: 4690580.1
G30: 2025 | H30: 1 | I30: 1600392.8 | J30: 348969.8
H31: 2 | I31: 1760164 | J31: 289990
H32: 3 | I32: 2041062.3 | J32: 390168.3
H33: 4 | I33: 2374974.4 | J33: 334507.35
H34: 5 | I34: 2883802.1 | J34: 505970.15
H35: 6 | I35: 2370427.9 | J35: 413895.85
H36: 7 | I36: 2620932.2 | J36: 479208.25
H37: 8 | I37: 3351826.3 | J37: 542538.3
H38: 9 | I38: 2223983 | J38: 389810.05
H39: 10 | I39: 2978583.6 | J39: 446654.65
H40: 11 | I40: 2898840.7 | J40: 602612.65
H41: 12 | I41: 2703484.8 | J41: 500544.8
G42: 2025 Total | I42: 29808474 | J42: 5244870.1
...

Sheet Targets
A1: Region | B1: Annual Revenue Target (INR) | C1: Target Margin %
A2: North | B2: 7500000 | C2: 0.2
A3: South | B3: 9000000 | C3: 0.2
A4: East | B4: 5000000 | C4: 0.2
A5: West | B5: 9500000 | C5: 0.2
A8: Note: targets are illustrative assumptions (blue = editable input). The dataset is synthetic, created for portfolio practice.
